Workbook

Sheet Parámetros
A1: Kipu Pay · Parámetros laborales
A2: Valores usados por todas las fórmulas. Celdas en azul = datos editables. Simulación académica.
A3: Parámetro | B3: Valor | C3: Fuente | D3: Fecha de consulta | E3: Nota
A4: RMV | B4: 1230 | C4: D.S. 015-2026-TR, vigente desde el 01/10/2026 | D4: 28/10/2026 | E4: Publicado en El Peruano.
A5: Asignación familiar (% de la RMV) | B5: 0.1 | C5: Ley 25129 | D5: 28/10/2026
A6: Asignación familiar (monto) | B6: =ROUND(B4*B5,2) | C6: Ley 25129 | D6: 28/10/2026 | E6: Calculado: RMV × 10%. No se prorratea por días.
A7: ONP | B7: 0.13 | C7: D.L. 19990 | D7: 28/10/2026 | E7: Sobre el total de remuneraciones.
A8: EsSalud (empleador) | B8: 0.09 | C8: Ley 26790 | D8: 28/10/2026 | E8: Lo paga el empleador; no se descuenta.
A9: Multiplicador horas extras 25% | B9: 1.25 | C9: Normas de jornada y sobretiempo | D9: 28/10/2026
A10: Multiplicador horas extras 35% | B10: 1.35 | C10: Normas de jornada y sobretiempo | D10: 28/10/2026
A11: Días del mes (divisor) | B11: 30 | C11: Convención del enunciado | D11: 28/10/2026
A12: Horas por jornada (divisor) | B12: 8 | C12: Convención del enunciado | D12: 28/10/2026
A13: Remuneración máxima asegurable (seguro AFP) | B13: 12732.7 | C13: SBS, comisiones y primas del SPP, devengue 10/2026 | D13: 28/10/2026 | E13: La prima de seguro AFP se calcula solo hasta este tope (vigente oct–dic 2026).
A14: Tasas de AFP (diccionario de tasas)
A15: AFP | B15: Fondo | C15: Comisión | D15: Seguro | E15: Fuente
A16: AFP Habitat · Flujo | B16: 0.1 | C16: 0.0147 | D16: 0.0137 | E16: SBS, devengue 10/2026 · comisión por flujo (mensual sobre la remuneración)
A17: AFP Habitat · Mixta | B17: 0.1 | C17: 0 | D17: 0.0137 | E17: SBS, devengue 10/2026 · mixta: 0% sobre la remuneración; 1.25% anual sobre el saldo (no va en la boleta)
A18: AFP Integra · Flujo | B18: 0.1 | C18: 0.0155 | D18: 0.0137 | E18: SBS, devengue 10/2026 · comisión por flujo (mensual sobre la remuneración)
A19: AFP Integra · Mixta | B19: 0.1 | C19: 0 | D19: 0.0137 | E19: SBS, devengue 10/2026 · mixta: 0% sobre la remuneración; 0.78% anual sobre el saldo (no va en la boleta)
A20: AFP Prima · Flujo | B20: 0.1 | C20: 0.016 | D20: 0.0137 | E20: SBS, devengue 10/2026 · comisión por flujo (mensual sobre la remuneración)
A21: AFP Prima · Mixta | B21: 0.1 | C21: 0 | D21: 0.0137 | E21: SBS, devengue 10/2026 · mixta: 0% sobre la remuneración; 1.25% anual sobre el saldo (no va en la boleta)
A22: AFP Profuturo · Flujo | B22: 0.1 | C22: 0.0169 | D22: 0.0137 | E22: SBS, devengue 10/2026 · comisión por flujo (mensual sobre la remuneración)
A23: AFP Profuturo · Mixta | B23: 0.1 | C23: 0 | D23: 0.0137 | E23: SBS, devengue 10/2026 · mixta: 0% sobre la remuneración; 0.68% anual sobre el saldo (no va en la boleta)
A24: AFP Ejemplo | B24: 0.1 | C24: 0.016 | D24: 0.0135 | E24: Valores de prueba del laboratorio, solo para los casos 3 y 4 (no es una AFP real)
E25: Filas 25–30 libres: agrega otra AFP con sus tasas de la SBS.
A32: Fuentes: SBS (sbs.gob.pe › SPP › Comisiones y primas de seguros), El Peruano (D.S. 015-2026-TR), Ley 25129, D.L. 19990, Ley 26790. Las tasas AFP cambian cada mes: actualízalas antes de usar el libro.

Sheet Boleta
A1: Kipu Pay · Boleta de pago (EJEMPLO)
A2: Escribe los datos en las celdas amarillas (columna B). Todo lo demás se calcula con fórmulas.
A4: Dato / Concepto | B4: Valor | C4: Cómo se calcula
A5: Sueldo básico (S/) | B5: 3000 | C5: Ejemplo: datos del Caso 3 con AFP Habitat (flujo). Cámbialos por tus datos.
A6: Días laborados (1–30) | B6: 30
A7: ¿Tiene hijos? (Sí/No) | B7: Sí
A8: Sistema de pensiones (ONP/AFP) | B8: AFP
A9: AFP (si eligió AFP) | B9: AFP Habitat · Flujo
A10: Horas extras al 25% | B10: 4
A11: Horas extras al 35% | B11: 4
A12: Adelantos (S/) | B12: 200
A13: Validación | B13: =IF(B5="","",IF(B6="","Falta días laborados",IF(OR(NOT(ISNUMBER(B5)),B5<=0),"Sueldo debe ser mayor que cero",IF(OR(NOT(ISNUMBER(B6)),B6<1,B6>30,B6<>INT(B6)),"Días: entero entre 1 y 30",IF(OR(N(B10)<0,N(B11)<0,N(B12)<0,N(B10)<>INT(N(B10)),N(B11)<>INT(N(B11))),"Horas (enteras) y adelantos deben ser ≥ 0",IF(AND(B8="AFP",ISNA(MATCH(B9,'Parámetros'!$A$16:$A$30,0))),"AFP sin tasas configuradas","Datos válidos"))))))
A15: A · REMUNERACIONES
A16: Sueldo computable | B16: =IF(B$5="","",ROUND(B5*B6/'Parámetros'!$B$11,2)) | C16: Básico × días ÷ 30, redondeado
A17: Asignación familiar | B17: =IF(B$5="","",IF(OR(B7="Sí",B7="Si"),'Parámetros'!$B$6,0)) | C17: 10% de la RMV si tiene hijos; no se prorratea
A18: Valor por hora (referencia) | B18: =IF(B$5="","",ROUND(B5/('Parámetros'!$B$11*'Parámetros'!$B$12),2)) | C18: Básico ÷ 30 ÷ 8, redondeado; no se suma
A19: Horas extras 25% | B19: =IF(B$5="","",ROUND(B18*'Parámetros'!$B$9*N(B10),2)) | C19: Valor hora × 1.25 × horas al 25%
A20: Horas extras 35% | B20: =IF(B$5="","",ROUND(B18*'Parámetros'!$B$10*N(B11),2)) | C20: Valor hora × 1.35 × horas al 35%
A21: TOTAL REMUNERACIONES | B21: =IF(B$5="","",B16+B17+B19+B20) | C21: Suma de los 4 conceptos anteriores
A23: B · RETENCIONES / DESCUENTOS
A24: ONP | B24: =IF(B$5="","",IF(B8="ONP",ROUND(B21*'Parámetros'!$B$7,2),0)) | C24: 13% del total, solo si es ONP
A25: AFP fondo | B25: =IF(B$5="","",IF(B8="AFP",ROUND(B21*INDEX('Parámetros'!$B$16:$B$30,MATCH(B9,'Parámetros'!$A$16:$A$30,0)),2),0)) | C25: Total × tasa de fondo, solo si es AFP
A26: AFP comisión | B26: =IF(B$5="","",IF(B8="AFP",ROUND(B21*INDEX('Parámetros'!$C$16:$C$30,MATCH(B9,'Parámetros'!$A$16:$A$30,0)),2),0)) | C26: Total × tasa de comisión, solo si es AFP
A27: AFP seguro | B27: =IF(B$5="","",IF(B8="AFP",ROUND(MIN(B21,'Parámetros'!$B$13)*INDEX('Parámetros'!$D$16:$D$30,MATCH(B9,'Parámetros'!$A$16:$A$30,0)),2),0)) | C27: Mín(total; rem. máx. asegurable) × tasa de seguro, solo si es AFP
A28: Adelantos | B28: =IF(B$5="","",ROUND(N(B12),2)) | C28: Monto ingresado, se resta tal cual
A29: TOTAL DESCUENTOS | B29: =IF(B$5="","",SUM(B24:B28)) | C29: Pensión + adelantos
A31: C · APORTACIONES DEL EMPLEADOR
A32: EsSalud (9%) | B32: =IF(B$5="","",ROUND(B21*'Parámetros'!$B$8,2)) | C32: 9% del total; lo paga el empleador
A34: NETO A PAGAR | B34: =IF(B5="","",IF(B13<>"Datos válidos","Revisar datos",B21-B29)) | C34: Total remuneraciones − total descuentos
A36: Boleta de ejemplo · Simulación académica. Valores a verificar antes de usarlos en una boleta real.

Sheet Casos
A1: Kipu Pay · Casos de prueba y control cruzado
A2: Mismas fórmulas que la hoja Boleta, una columna por caso. Casos 3 y 4 con AFP Ejemplo, como pide el enunciado. Columna I: caso propio.
I3: Sueldo de una oferta real (≥ RMV). Anota enlace y fecha abajo.
A4: Dato / Concepto | B4: Caso 1 | C4: Caso 2 | D4: Caso 3 | E4: Caso 4 | F4: Caso 3 con ONP (pregunta 1) | G4: Caso 2 con 30 días (pregunta 3) | H4: Caso 3 con AFP Habitat · Flujo | I4: Caso propio
A5: Sueldo básico (S/) | B5: 2500 | C5: 1800 | D5: 3000 | E5: 4200 | F5: 3000 | G5: 1800 | H5: 3000
A6: Días laborados (1–30) | B6: 30 | C6: 27 | D6: 30 | E6: 24 | F6: 30 | G6: 30 | H6: 30
A7: ¿Tiene hijos? (Sí/No) | B7: No | C7: Sí | D7: Sí | E7: Sí | F7: Sí | G7: Sí | H7: Sí
A8: Sistema de pensiones (ONP/AFP) | B8: ONP | C8: ONP | D8: AFP | E8: AFP | F8: ONP | G8: ONP | H8: AFP
A9: AFP (si eligió AFP) | D9: AFP Ejemplo | E9: AFP Ejemplo | H9: AFP Habitat · Flujo
A10: Horas extras al 25% | B10: 0 | C10: 0 | D10: 4 | E10: 2 | F10: 4 | G10: 0 | H10: 4
A11: Horas extras al 35% | B11: 0 | C11: 0 | D11: 4 | E11: 2 | F11: 4 | G11: 0 | H11: 4
A12: Adelantos (S/) | B12: 0 | C12: 0 | D12: 200 | E12: 100 | F12: 200 | G12: 0 | H12: 200
A13: Validación | B13: =IF(B5="","",IF(B6="","Falta días laborados",IF(OR(NOT(ISNUMBER(B5)),B5<=0),"Sueldo debe ser mayor que cero",IF(OR(NOT(ISNUMBER(B6)),B6<1,B6>30,B6<>INT(B6)),"Días: entero entre 1 y 30",IF(OR(N(B10)<0,N(B11)<0,N(B12)<0,N(B10)<>INT(N(B10)),N(B11)<>INT(N(B11))),"Horas (enteras) y adelantos deben ser ≥ 0",IF(AND(B8="AFP",ISNA(MATCH(B9,'Parámetros'!$A$16:$A$30,0))),"AFP sin tasas configuradas","Datos válidos")))))) | C13: =IF(C5="","",IF(C6="","Falta días laborados",IF(OR(NOT(ISNUMBER(C5)),C5<=0),"Sueldo debe ser mayor que cero",IF(OR(NOT(ISNUMBER(C6)),C6<1,C6>30,C6<>INT(C6)),"Días: entero entre 1 y 30",IF(OR(N(C10)<0,N(C11)<0,N(C12)<0,N(C10)<>INT(N(C10)),N(C11)<>INT(N(C11))),"Horas (enteras) y adelantos deben ser ≥ 0",IF(AND(C8="AFP",ISNA(MATCH(C9,'Parámetros'!$A$16:$A$30,0))),"AFP sin tasas configuradas","Datos válidos")))))) | D13: =IF(D5="","",IF(D6="","Falta días laborados",IF(OR(NOT(ISNUMBER(D5)),D5<=0),"Sueldo debe ser mayor que cero",IF(OR(NOT(ISNUMBER(D6)),D6<1,D6>30,D6<>INT(D6)),"Días: entero entre 1 y 30",IF(OR(N(D10)<0,N(D11)<0,N(D12)<0,N(D10)<>INT(N(D10)),N(D11)<>INT(N(D11))),"Horas (enteras) y adelantos deben ser ≥ 0",IF(AND(D8="AFP",ISNA(MATCH(D9,'Parámetros'!$A$16:$A$30,0))),"AFP sin tasas configuradas","Datos válidos")))))) | E13: =IF(E5="","",IF(E6="","Falta días laborados",IF(OR(NOT(ISNUMBER(E5)),E5<=0),"Sueldo debe ser mayor que cero",IF(OR(NOT(ISNUMBER(E6)),E6<1,E6>30,E6<>INT(E6)),"Días: entero entre 1 y 30",IF(OR(N(E10)<0,N(E11)<0,N(E12)<0,N(E10)<>INT(N(E10)),N(E11)<>INT(N(E11))),"Horas (enteras) y adelantos deben ser ≥ 0",IF(AND(E8="AFP",ISNA(MATCH(E9,'Parámetros'!$A$16:$A$30,0))),"AFP sin tasas configuradas","Datos válidos")))))) | F13: =IF(F5="","",IF(F6="","Falta días laborados",IF(OR(NOT(ISNUMBER(F5)),F5<=0),"Sueldo debe ser mayor que cero",IF(OR(NOT(ISNUMBER(F6)),F6<1,F6>30,F6<>INT(F6)),"Días: entero entre 1 y 30",IF(OR(N(F10)<0,N(F11)<0,N(F12)<0,N(F10)<>INT(N(F10)),N(F11)<>INT(N(F11))),"Horas (enteras) y adelantos deben ser ≥ 0",IF(AND(F8="AFP",ISNA(MATCH(F9,'Parámetros'!$A$16:$A$30,0))),"AFP sin tasas configuradas","Datos válidos")))))) | G13: =IF(G5="","",IF(G6="","Falta días laborados",IF(OR(NOT(ISNUMBER(G5)),G5<=0),"Sueldo debe ser mayor que cero",IF(OR(NOT(ISNUMBER(G6)),G6<1,G6>30,G6<>INT(G6)),"Días: entero entre 1 y 30",IF(OR(N(G10)<0,N(G11)<0,N(G12)<0,N(G10)<>INT(N(G10)),N(G11)<>INT(N(G11))),"Horas (enteras) y adelantos deben ser ≥ 0",IF(AND(G8="AFP",ISNA(MATCH(G9,'Parámetros'!$A$16:$A$30,0))),"AFP sin tasas configuradas","Datos válidos")))))) | H13: =IF(H5="","",IF(H6="","Falta días laborados",IF(OR(NOT(ISNUMBER(H5)),H5<=0),"Sueldo debe ser mayor que cero",IF(OR(NOT(ISNUMBER(H6)),H6<1,H6>30,H6<>INT(H6)),"Días: entero entre 1 y 30",IF(OR(N(H10)<0,N(H11)<0,N(H12)<0,N(H10)<>INT(N(H10)),N(H11)<>INT(N(H11))),"Horas (enteras) y adelantos deben ser ≥ 0",IF(AND(H8="AFP",ISNA(MATCH(H9,'Parámetros'!$A$16:$A$30,0))),"AFP sin tasas configuradas","Datos válidos")))))) | I13: =IF(I5="","",IF(I6="","Falta días laborados",IF(OR(NOT(ISNUMBER(I5)),I5<=0),"Sueldo debe ser mayor que cero",IF(OR(NOT(ISNUMBER(I6)),I6<1,I6>30,I6<>INT(I6)),"Días: entero entre 1 y 30",IF(OR(N(I10)<0,N(I11)<0,N(I12)<0,N(I10)<>INT(N(I10)),N(I11)<>INT(N(I11))),"Horas (enteras) y adelantos deben ser ≥ 0",IF(AND(I8="AFP",ISNA(MATCH(I9,'Parámetros'!$A$16:$A$30,0))),"AFP sin tasas configuradas","Datos válidos"))))))
A15: A · REMUNERACIONES
A16: Sueldo computable | B16: =IF(B$5="","",ROUND(B5*B6/'Parámetros'!$B$11,2)) | C16: =IF(C$5="","",ROUND(C5*C6/'Parámetros'!$B$11,2)) | D16: =IF(D$5="","",ROUND(D5*D6/'Parámetros'!$B$11,2)) | E16: =IF(E$5="","",ROUND(E5*E6/'Parámetros'!$B$11,2)) | F16: =IF(F$5="","",ROUND(F5*F6/'Parámetros'!$B$11,2)) | G16: =IF(G$5="","",ROUND(G5*G6/'Parámetros'!$B$11,2)) | H16: =IF(H$5="","",ROUND(H5*H6/'Parámetros'!$B$11,2)) | I16: =IF(I$5="","",ROUND(I5*I6/'Parámetros'!$B$11,2))
A17: Asignación familiar | B17: =IF(B$5="","",IF(OR(B7="Sí",B7="Si"),'Parámetros'!$B$6,0)) | C17: =IF(C$5="","",IF(OR(C7="Sí",C7="Si"),'Parámetros'!$B$6,0)) | D17: =IF(D$5="","",IF(OR(D7="Sí",D7="Si"),'Parámetros'!$B$6,0)) | E17: =IF(E$5="","",IF(OR(E7="Sí",E7="Si"),'Parámetros'!$B$6,0)) | F17: =IF(F$5="","",IF(OR(F7="Sí",F7="Si"),'Parámetros'!$B$6,0)) | G17: =IF(G$5="","",IF(OR(G7="Sí",G7="Si"),'Parámetros'!$B$6,0)) | H17: =IF(H$5="","",IF(OR(H7="Sí",H7="Si"),'Parámetros'!$B$6,0)) | I17: =IF(I$5="","",IF(OR(I7="Sí",I7="Si"),'Parámetros'!$B$6,0))
A18: Valor por hora (referencia) | B18: =IF(B$5="","",ROUND(B5/('Parámetros'!$B$11*'Parámetros'!$B$12),2)) | C18: =IF(C$5="","",ROUND(C5/('Parámetros'!$B$11*'Parámetros'!$B$12),2)) | D18: =IF(D$5="","",ROUND(D5/('Parámetros'!$B$11*'Parámetros'!$B$12),2)) | E18: =IF(E$5="","",ROUND(E5/('Parámetros'!$B$11*'Parámetros'!$B$12),2)) | F18: =IF(F$5="","",ROUND(F5/('Parámetros'!$B$11*'Parámetros'!$B$12),2)) | G18: =IF(G$5="","",ROUND(G5/('Parámetros'!$B$11*'Parámetros'!$B$12),2)) | H18: =IF(H$5="","",ROUND(H5/('Parámetros'!$B$11*'Parámetros'!$B$12),2)) | I18: =IF(I$5="","",ROUND(I5/('Parámetros'!$B$11*'Parámetros'!$B$12),2))
A19: Horas extras 25% | B19: =IF(B$5="","",ROUND(B18*'Parámetros'!$B$9*N(B10),2)) | C19: =IF(C$5="","",ROUND(C18*'Parámetros'!$B$9*N(C10),2)) | D19: =IF(D$5="","",ROUND(D18*'Parámetros'!$B$9*N(D10),2)) | E19: =IF(E$5="","",ROUND(E18*'Parámetros'!$B$9*N(E10),2)) | F19: =IF(F$5="","",ROUND(F18*'Parámetros'!$B$9*N(F10),2)) | G19: =IF(G$5="","",ROUND(G18*'Parámetros'!$B$9*N(G10),2)) | H19: =IF(H$5="","",ROUND(H18*'Parámetros'!$B$9*N(H10),2)) | I19: =IF(I$5="","",ROUND(I18*'Parámetros'!$B$9*N(I10),2))
A20: Horas extras 35% | B20: =IF(B$5="","",ROUND(B18*'Parámetros'!$B$10*N(B11),2)) | C20: =IF(C$5="","",ROUND(C18*'Parámetros'!$B$10*N(C11),2)) | D20: =IF(D$5="","",ROUND(D18*'Parámetros'!$B$10*N(D11),2)) | E20: =IF(E$5="","",ROUND(E18*'Parámetros'!$B$10*N(E11),2)) | F20: =IF(F$5="","",ROUND(F18*'Parámetros'!$B$10*N(F11),2)) | G20: =IF(G$5="","",ROUND(G18*'Parámetros'!$B$10*N(G11),2)) | H20: =IF(H$5="","",ROUND(H18*'Parámetros'!$B$10*N(H11),2)) | I20: =IF(I$5="","",ROUND(I18*'Parámetros'!$B$10*N(I11),2))
A21: TOTAL REMUNERACIONES | B21: =IF(B$5="","",B16+B17+B19+B20) | C21: =IF(C$5="","",C16+C17+C19+C20) | D21: =IF(D$5="","",D16+D17+D19+D20) | E21: =IF(E$5="","",E16+E17+E19+E20) | F21: =IF(F$5="","",F16+F17+F19+F20) | G21: =IF(G$5="","",G16+G17+G19+G20) | H21: =IF(H$5="","",H16+H17+H19+H20) | I21: =IF(I$5="","",I16+I17+I19+I20)
A23: B · RETENCIONES / DESCUENTOS
A24: ONP | B24: =IF(B$5="","",IF(B8="ONP",ROUND(B21*'Parámetros'!$B$7,2),0)) | C24: =IF(C$5="","",IF(C8="ONP",ROUND(C21*'Parámetros'!$B$7,2),0)) | D24: =IF(D$5="","",IF(D8="ONP",ROUND(D21*'Parámetros'!$B$7,2),0)) | E24: =IF(E$5="","",IF(E8="ONP",ROUND(E21*'Parámetros'!$B$7,2),0)) | F24: =IF(F$5="","",IF(F8="ONP",ROUND(F21*'Parámetros'!$B$7,2),0)) | G24: =IF(G$5="","",IF(G8="ONP",ROUND(G21*'Parámetros'!$B$7,2),0)) | H24: =IF(H$5="","",IF(H8="ONP",ROUND(H21*'Parámetros'!$B$7,2),0)) | I24: =IF(I$5="","",IF(I8="ONP",ROUND(I21*'Parámetros'!$B$7,2),0))
A25: AFP fondo | B25: =IF(B$5="","",IF(B8="AFP",ROUND(B21*INDEX('Parámetros'!$B$16:$B$30,MATCH(B9,'Parámetros'!$A$16:$A$30,0)),2),0)) | C25: =IF(C$5="","",IF(C8="AFP",ROUND(C21*INDEX('Parámetros'!$B$16:$B$30,MATCH(C9,'Parámetros'!$A$16:$A$30,0)),2),0)) | D25: =IF(D$5="","",IF(D8="AFP",ROUND(D21*INDEX('Parámetros'!$B$16:$B$30,MATCH(D9,'Parámetros'!$A$16:$A$30,0)),2),0)) | E25: =IF(E$5="","",IF(E8="AFP",ROUND(E21*INDEX('Parámetros'!$B$16:$B$30,MATCH(E9,'Parámetros'!$A$16:$A$30,0)),2),0)) | F25: =IF(F$5="","",IF(F8="AFP",ROUND(F21*INDEX('Parámetros'!$B$16:$B$30,MATCH(F9,'Parámetros'!$A$16:$A$30,0)),2),0)) | G25: =IF(G$5="","",IF(G8="AFP",ROUND(G21*INDEX('Parámetros'!$B$16:$B$30,MATCH(G9,'Parámetros'!$A$16:$A$30,0)),2),0)) | H25: =IF(H$5="","",IF(H8="AFP",ROUND(H21*INDEX('Parámetros'!$B$16:$B$30,MATCH(H9,'Parámetros'!$A$16:$A$30,0)),2),0)) | I25: =IF(I$5="","",IF(I8="AFP",ROUND(I21*INDEX('Parámetros'!$B$16:$B$30,MATCH(I9,'Parámetros'!$A$16:$A$30,0)),2),0))
A26: AFP comisión | B26: =IF(B$5="","",IF(B8="AFP",ROUND(B21*INDEX('Parámetros'!$C$16:$C$30,MATCH(B9,'Parámetros'!$A$16:$A$30,0)),2),0)) | C26: =IF(C$5="","",IF(C8="AFP",ROUND(C21*INDEX('Parámetros'!$C$16:$C$30,MATCH(C9,'Parámetros'!$A$16:$A$30,0)),2),0)) | D26: =IF(D$5="","",IF(D8="AFP",ROUND(D21*INDEX('Parámetros'!$C$16:$C$30,MATCH(D9,'Parámetros'!$A$16:$A$30,0)),2),0)) | E26: =IF(E$5="","",IF(E8="AFP",ROUND(E21*INDEX('Parámetros'!$C$16:$C$30,MATCH(E9,'Parámetros'!$A$16:$A$30,0)),2),0)) | F26: =IF(F$5="","",IF(F8="AFP",ROUND(F21*INDEX('Parámetros'!$C$16:$C$30,MATCH(F9,'Parámetros'!$A$16:$A$30,0)),2),0)) | G26: =IF(G$5="","",IF(G8="AFP",ROUND(G21*INDEX('Parámetros'!$C$16:$C$30,MATCH(G9,'Parámetros'!$A$16:$A$30,0)),2),0)) | H26: =IF(H$5="","",IF(H8="AFP",ROUND(H21*INDEX('Parámetros'!$C$16:$C$30,MATCH(H9,'Parámetros'!$A$16:$A$30,0)),2),0)) | I26: =IF(I$5="","",IF(I8="AFP",ROUND(I21*INDEX('Parámetros'!$C$16:$C$30,MATCH(I9,'Parámetros'!$A$16:$A$30,0)),2),0))
A27: AFP seguro | B27: =IF(B$5="","",IF(B8="AFP",ROUND(MIN(B21,'Parámetros'!$B$13)*INDEX('Parámetros'!$D$16:$D$30,MATCH(B9,'Parámetros'!$A$16:$A$30,0)),2),0)) | C27: =IF(C$5="","",IF(C8="AFP",ROUND(MIN(C21,'Parámetros'!$B$13)*INDEX('Parámetros'!$D$16:$D$30,MATCH(C9,'Parámetros'!$A$16:$A$30,0)),2),0)) | D27: =IF(D$5="","",IF(D8="AFP",ROUND(MIN(D21,'Parámetros'!$B$13)*INDEX('Parámetros'!$D$16:$D$30,MATCH(D9,'Parámetros'!$A$16:$A$30,0)),2),0)) | E27: =IF(E$5="","",IF(E8="AFP",ROUND(MIN(E21,'Parámetros'!$B$13)*INDEX('Parámetros'!$D$16:$D$30,MATCH(E9,'Parámetros'!$A$16:$A$30,0)),2),0)) | F27: =IF(F$5="","",IF(F8="AFP",ROUND(MIN(F21,'Parámetros'!$B$13)*INDEX('Parámetros'!$D$16:$D$30,MATCH(F9,'Parámetros'!$A$16:$A$30,0)),2),0)) | G27: =IF(G$5="","",IF(G8="AFP",ROUND(MIN(G21,'Parámetros'!$B$13)*INDEX('Parámetros'!$D$16:$D$30,MATCH(G9,'Parámetros'!$A$16:$A$30,0)),2),0)) | H27: =IF(H$5="","",IF(H8="AFP",ROUND(MIN(H21,'Parámetros'!$B$13)*INDEX('Parámetros'!$D$16:$D$30,MATCH(H9,'Parámetros'!$A$16:$A$30,0)),2),0)) | I27: =IF(I$5="","",IF(I8="AFP",ROUND(MIN(I21,'Parámetros'!$B$13)*INDEX('Parámetros'!$D$16:$D$30,MATCH(I9,'Parámetros'!$A$16:$A$30,0)),2),0))
A28: Adelantos | B28: =IF(B$5="","",ROUND(N(B12),2)) | C28: =IF(C$5="","",ROUND(N(C12),2)) | D28: =IF(D$5="","",ROUND(N(D12),2)) | E28: =IF(E$5="","",ROUND(N(E12),2)) | F28: =IF(F$5="","",ROUND(N(F12),2)) | G28: =IF(G$5="","",ROUND(N(G12),2)) | H28: =IF(H$5="","",ROUND(N(H12),2)) | I28: =IF(I$5="","",ROUND(N(I12),2))
A29: TOTAL DESCUENTOS | B29: =IF(B$5="","",SUM(B24:B28)) | C29: =IF(C$5="","",SUM(C24:C28)) | D29: =IF(D$5="","",SUM(D24:D28)) | E29: =IF(E$5="","",SUM(E24:E28)) | F29: =IF(F$5="","",SUM(F24:F28)) | G29: =IF(G$5="","",SUM(G24:G28)) | H29: =IF(H$5="","",SUM(H24:H28)) | I29: =IF(I$5="","",SUM(I24:I28))
A31: C · APORTACIONES DEL EMPLEADOR
A32: EsSalud (9%) | B32: =IF(B$5="","",ROUND(B21*'Parámetros'!$B$8,2)) | C32: =IF(C$5="","",ROUND(C21*'Parámetros'!$B$8,2)) | D32: =IF(D$5="","",ROUND(D21*'Parámetros'!$B$8,2)) | E32: =IF(E$5="","",ROUND(E21*'Parámetros'!$B$8,2)) | F32: =IF(F$5="","",ROUND(F21*'Parámetros'!$B$8,2)) | G32: =IF(G$5="","",ROUND(G21*'Parámetros'!$B$8,2)) | H32: =IF(H$5="","",ROUND(H21*'Parámetros'!$B$8,2)) | I32: =IF(I$5="","",ROUND(I21*'Parámetros'!$B$8,2))
A34: NETO A PAGAR | B34: =IF(B5="","",IF(B13<>"Datos válidos","Revisar datos",B21-B29)) | C34: =IF(C5="","",IF(C13<>"Datos válidos","Revisar datos",C21-C29)) | D34: =IF(D5="","",IF(D13<>"Datos válidos","Revisar datos",D21-D29)) | E34: =IF(E5="","",IF(E13<>"Datos válidos","Revisar datos",E21-E29)) | F34: =IF(F5="","",IF(F13<>"Datos válidos","Revisar datos",F21-F29)) | G34: =IF(G5="","",IF(G13<>"Datos válidos","Revisar datos",G21-G29)) | H34: =IF(H5="","",IF(H13<>"Datos válidos","Revisar datos",H21-H29)) | I34: =IF(I5="","",IF(I13<>"Datos válidos","Revisar datos",I21-I29))
A36: CONTROL CRUZADO
A37: Neto esperado (documento) | B37: 2175 | C37: 1516.41 | D37: 2631.73
A38: Neto en la app | B38: 2175 | C38: 1516.41 | D38: 2631.73 | E38: 3011.17 | H38: 2635.31
A39: Total descuentos en la app | B39: 325 | C39: 226.59 | D39: 621.27 | E39: 562.83 | H39: 617.69
A40: EsSalud en la app | B40: 225 | C40: 156.87 | D40: 292.77 | E40: 321.66 | H40: 292.77
A41: ¿Excel = documento? | B41: =IF(B37="","—",IF(ABS(B34-B37)<0.005,"✓ Coincide","✗ Revisar")) | C41: =IF(C37="","—",IF(ABS(C34-C37)<0.005,"✓ Coincide","✗ Revisar")) | D41: =IF(D37="","—",IF(ABS(D34-D37)<0.005,"✓ Coincide","✗ Revisar")) | E41: =IF(E37="","—",IF(ABS(E34-E37)<0.005,"✓ Coincide","✗ Revisar")) | F41: =IF(F37="","—",IF(ABS(F34-F37)<0.005,"✓ Coincide","✗ Revisar")) | G41: =IF(G37="","—",IF(ABS(G34-G37)<0.005,"✓ Coincide","✗ Revisar")) | H41: =IF(H37="","—",IF(ABS(H34-H37)<0.005,"✓ Coincide","✗ Revisar")) | I41: =IF(I37="","—",IF(ABS(I34-I37)<0.005,"✓ Coincide","✗ Revisar"))
A42: ¿Excel = app? | B42: =IF(B38="","—",IF(AND(ABS(B34-B38)<0.005,ABS(B29-B39)<0.005,ABS(B32-B40)<0.005),"✓ Coincide","✗ Revisar")) | C42: =IF(C38="","—",IF(AND(ABS(C34-C38)<0.005,ABS(C29-C39)<0.005,ABS(C32-C40)<0.005),"✓ Coincide","✗ Revisar")) | D42: =IF(D38="","—",IF(AND(ABS(D34-D38)<0.005,ABS(D29-D39)<0.005,ABS(D32-D40)<0.005),"✓ Coincide","✗ Revisar")) | E42: =IF(E38="","—",IF(AND(ABS(E34-E38)<0.005,ABS(E29-E39)<0.005,ABS(E32-E40)<0.005),"✓ Coincide","✗ Revisar")) | F42: =IF(F38="","—",IF(AND(ABS(F34-F38)<0.005,ABS(F29-F39)<0.005,ABS(F32-F40)<0.005),"✓ Coincide","✗ Revisar")) | G42: =IF(G38="","—",IF(AND(ABS(G34-G38)<0.005,ABS(G29-G39)<0.005,ABS(G32-G40)<0.005),"✓ Coincide","✗ Revisar")) | H42: =IF(H38="","—",IF(AND(ABS(H34-H38)<0.005,ABS(H29-H39)<0.005,ABS(H32-H40)<0.005),"✓ Coincide","✗ Revisar")) | I42: =IF(I38="","—",IF(AND(ABS(I34-I38)<0.005,ABS(I29-I39)<0.005,ABS(I32-I40)<0.005),"✓ Coincide","✗ Revisar"))
A44: INDICADORES PARA EL ANÁLISIS
A45: Costo para el empleador (remuneraciones + EsSalud) | B45: =IF(B5="","",B21+B32) | C45: =IF(C5="","",C21+C32) | D45: =IF(D5="","",D21+D32) | E45: =IF(E5="","",E21+E32) | F45: =IF(F5="","",F21+F32) | G45: =IF(G5="","",G21+G32) | H45: =IF(H5="","",H21+H32) | I45: =IF(I5="","",I21+I32)
A46: % del costo que llega como neto | B46: =IF(OR(B5="",N(B45)=0),"",B34/B45) | C46: =IF(OR(C5="",N(C45)=0),"",C34/C45) | D46: =IF(OR(D5="",N(D45)=0),"",D34/D45) | E46: =IF(OR(E5="",N(E45)=0),"",E34/E45) | F46: =IF(OR(F5="",N(F45)=0),"",F34/F45) | G46: =IF(OR(G5="",N(G45)=0),"",G34/G45) | H46: =IF(OR(H5="",N(H45)=0),"",H34/H45) | I46: =IF(OR(I5="",N(I45)=0),"",I34/I45)
...

Sheet Explicación
A1: Kipu Pay · Cómo se calcula la boleta
A2: Cada fórmula en palabras, con el Caso 3 (AFP Ejemplo) como ejemplo numérico. Pensado para quien no sabe contabilidad.
A4: Concepto | B4: Qué significa | C4: Fórmula en palabras | D4: Ejemplo (Caso 3) | E4: Resultado (Casos!D)
A5: Sueldo computable | B5: La parte del sueldo que corresponde a los días que realmente trabajaste. | C5: Sueldo básico × días laborados ÷ 30 | D5: 3,000 × 30 ÷ 30 | E5: =Casos!D16
A6: Asignación familiar | B6: Un monto fijo para quien tiene hijos. No baja aunque faltes días. | C6: Si tiene hijos: 10% de la RMV. Si no: 0 | D6: 10% × 1,230 | E6: =Casos!D17
A7: Valor por hora | B7: Cuánto vale una hora normal de trabajo. Sirve para pagar las horas extras. | C7: Sueldo básico ÷ 30 ÷ 8 (redondeado a 2 decimales) | D7: 3,000 ÷ 30 ÷ 8 | E7: =Casos!D18
A8: Horas extras 25% | B8: Las primeras horas extra se pagan 25% más caras que una hora normal. | C8: Valor hora × 1.25 × horas al 25% | D8: 12.50 × 1.25 × 4 | E8: =Casos!D19
A9: Horas extras 35% | B9: Las horas extra siguientes se pagan 35% más caras. | C9: Valor hora × 1.35 × horas al 35% | D9: 12.50 × 1.35 × 4 | E9: =Casos!D20
A10: Total remuneraciones | B10: Todo lo que ganaste en el mes, antes de descuentos (el "bruto"). | C10: Sueldo computable + asignación + horas extras 25% + horas extras 35% | D10: 3,000 + 123 + 62.50 + 67.50 | E10: =Casos!D21
A11: ONP | B11: Aporte al sistema público de pensiones. Solo si estás en la ONP. | C11: Total remuneraciones × 13% | D11: No aplica (está en AFP) | E11: =Casos!D24
A12: AFP fondo | B12: Lo que va a tu cuenta personal de jubilación en la AFP. | C12: Total remuneraciones × tasa de fondo | D12: 3,253 × 10% = 325.30 | E12: =Casos!D25
A13: AFP comisión | B13: Lo que cobra la AFP por administrar tu fondo. En la modalidad mixta es 0% en la boleta (se cobra sobre el saldo). | C13: Total remuneraciones × tasa de comisión | D13: 3,253 × 1.60% = 52.048 | E13: =Casos!D26
A14: AFP seguro | B14: Seguro de invalidez, sobrevivencia y gastos de sepelio. Solo se cobra hasta un tope de sueldo. | C14: Mínimo entre el total de remuneraciones y la remuneración máxima asegurable × tasa de seguro | D14: 3,253 × 1.35% = 43.9155 | E14: =Casos!D27
A15: Adelantos | B15: Dinero que ya recibiste antes durante el mes; se descuenta tal cual. | C15: Monto ingresado | D15: 200.00 | E15: =Casos!D28
A16: Total descuentos | B16: Todo lo que se resta de tu sueldo. | C16: Pensión (ONP o AFP) + adelantos | D16: 325.30 + 52.05 + 43.92 + 200 | E16: =Casos!D29
A17: Neto a pagar | B17: Lo que realmente llega a tu cuenta. | C17: Total remuneraciones − total descuentos | D17: 3,253.00 − 621.27 | E17: =Casos!D34
A18: EsSalud | B18: Seguro de salud que paga la empresa, aparte de tu sueldo. No te lo descuentan. | C18: Total remuneraciones × 9% | D18: 3,253 × 9% = 292.77 | E18: =Casos!D32
A20: Convenciones
A21: • Cada concepto se redondea a 2 decimales (REDONDEAR / ROUND) y después se suman.
A22: • El valor por hora también se redondea a 2 decimales antes de calcular las horas extras (el documento lo muestra como 12.50).
A23: • El sueldo computable se calcula como básico × días ÷ 30 (misma fórmula; dividir al final evita errores de redondeo).
A24: • ONP y AFP se calculan sobre el total de remuneraciones (incluye asignación familiar y horas extras). Nunca se aplican los dos.
A25: • La prima de seguro AFP se calcula solo hasta la remuneración máxima asegurable (S/ 12,732.70, oct–dic 2026). El fondo y la comisión no tienen tope.
A26: • No se calcula renta de 5.ª categoría. Las faltas ya están reflejadas en los días laborados.
A27: • EsSalud no tiene base mínima en este ejercicio y no se descuenta del neto.
A30: Preguntas de análisis
A31: Pregunta | B31: Cifra clave | C31: Valor | D31: Respuesta
A32: 1. ONP o AFP (Caso 3) | B32: Neto con AFP Ejemplo | C32: =Casos!D34 | D32: Con AFP Ejemplo el trabajador recibe un poco más este mes (ver diferencia). Comparar porcentajes no basta: en la AFP el fondo (10%) es ahorro en una cuenta propia, mientras que la comisión y el seguro son costos; cada AFP cobra tasas distintas y la pensión final depende de la rentabilidad. En la ONP el 13% va a un fondo común y la pensión depende de los años de aporte.
B33: Neto con ONP | C33: =Casos!F34
B34: Diferencia (AFP − ONP) | C34: =Casos!D34-Casos!F34
A35: 2. Costo real para la empresa (Caso 3) | B35: Remuneraciones + EsSalud | C35: =Casos!D45 | D35: La empresa paga el total de remuneraciones más EsSalud. Del costo total, al trabajador le llega como neto el porcentaje indicado; el resto son pensión, adelantos ya cobrados y EsSalud.
B36: % del costo que llega como neto | C36: =Casos!D46
A37: 3. Días laborados (Caso 2) | B37: Neto con 27 días | C37: =Casos!C34 | D37: La diferencia en el neto es menor que en el bruto porque al ganar más también sube el descuento de ONP: de cada sol adicional se retiene 13%, así que el neto sube solo 87% de la diferencia bruta.
B38: Neto con 30 días | C38: =Casos!G34
B39: Diferencia en el bruto | C39: =Casos!G21-Casos!C21
B40: Diferencia en el neto | C40: =Casos!G34-Casos!C34
A41: 4. Horas extras (Caso 3) | B41: % del total de remuneraciones | C41: =Casos!D48 | D41: Las horas extras (62.50 + 67.50 = 130.00) representan este porcentaje del total de remuneraciones.
A42: 5. Con datos reales | B42: % del bruto que llega como neto (caso propio) | C42: =Casos!I47 | D42: Completar: ingresa en Casos!I el sueldo de una oferta real (≥ RMV), anota enlace y fecha, y compara este porcentaje con el de dos compañeros.
